<!DOCTYPE html>
<html lang="ru"><head>
  <meta charset="utf-8">
  <meta http-equiv="X-UA-Compatible" content="IE=edge">
  <meta name="viewport" content="width=device-width, initial-scale=1"><!-- Begin Jekyll SEO tag v2.5.0 -->
<title>Обработка ошибок в async/await | ivalentinee</title>
<meta name="generator" content="Jekyll v3.8.5" />
<meta property="og:title" content="Обработка ошибок в async/await" />
<meta property="og:locale" content="ru" />
<meta name="description" content="Введение Совершенно внезапно для себя около года назад я начал писать на NodeJS. Не очень хотелось, но выбор был небольшой — нужна кросс-сборка приложения и в браузер и на сервер. Оказалось, что для многих концепция async/await в JS — сложная тема. И, если в большинстве случаев TypeScript не даст совершить ошибку при работе с async/await, то в этой ситуации код получается корректный (с точки зрения синтаксиса и проверки типов), а программа работает не так, как задумывалось. Проблема Проблема возникает при отлове ошибки в async-функциях. Вопрос Приведу два примера: // --- Пример 1 async function something() { // ... return await someOtherAsyncFunction(); // ... // --- Пример 2 async function something() { // ... return someOtherAsyncFunction(); // ... Можете попробовать угадать, что не так с этим кодом? Даже eslint помечает код в примере 1 как некорректный, за что eslint отдельное “спасибо”. Ответ Теперь приведу код, запустив который будет понятно, что не так со вторым примером: async function fail() { throw new Error(&#39;Ultimate failure&#39;); } await (async () =&gt; { try { return await fail(); } catch (error) { console.log(&#39;The error was caught&#39;); } })(); await (async () =&gt; { try { return fail(); } catch (error) { console.log(&#39;The error was not caught&#39;); } })(); Как следует из кода выше, &#39;The error was not caught&#39; не будет выведен, потому что во втором случае ошибка не будет поймана. Объяснение Чтобы понять, почему так происходит, нужно немного копнуть вглубь async/await (но не слишком). Async/await — всего лишь обёртка над промисами, которые в свою очередь являются всего лишь обёрткой над колбеками. Сумма этих двух обёрток позволяет писать асинхронный (с колбеками) код в превдо-синхронном стиле (без колбеков). Async-функции Объявление функции с async позволяет в теле функции использовать await. Кроме этого, если результатом async-функции является не промис, async-функция автоматически заворачивает значение в промис (что-то вроде Promise.resolve(value)). Пример: async function returnNumber() { return 1; } console.log(returnNumber()); // Promise { 1 } И, наконец, если в теле async-функции происходит выбрасывание исключения, это исключение тоже автоматически заворачивается в промис (что-то вроде Promise.reject(exception)). Пример: async function fail() { throw new Error(&#39;Ultimate failure&#39;); } console.log(fail()); // Promise { &lt;rejected&gt; Error: Ultimate failure } Await и разворачивание промисов Await-же занимается разворачиванием промисов, возвращённых из той функции, которая вызывалась с ключевым словом await: async function returnNumber() { return 1; } console.log(await returnNumber()); // 1 И, если вернулся промис с reject‘ом, ошибка из этого промиса заново бросается (и затем заново возвращается через Promise.reject, если не будет поймана в try-catch): async function fail() { throw new Error(&#39;Ultimate failure&#39;); } console.log(await fail()); // console.log ничего не выведет, будет только &#39;Uncaught Error: Ultimate failure&#39; «Кто виноват?» и «Что делать?» В результате, если в последнем try-catch (вверх по стеку) не написать await перед потенциально-выбрасывающей-исключение-функцией, промис (с reject-ом) отправится как есть и блок try-catch не перейдёт в секцию catch. В таком случае исключение вместо обработки будет выброшено. И если в браузере выбрашенное исключение приведёт только к красной строчке в инспекторе, то в случае сервера весь процесс ляжет (если не пользоваться совсем неприличными способами вроде process.on(&#39;uncaughtException&#39;, (error: Error) =&gt; { /* ... */ });) и в лучшем случае будет автоматически перезапущен (потеряв все данные). Что делать? Стараться возвращать результаты асинхронных функций через await даже тогда, когда это кажется нелогичным внутри try-catch-блоков: try { const result = await fail(); return result; } catch (error) { logger.log(error); return undefined; } И всегда вызывать асинхронные функции через await — даже если те возвращают пустой промис (Promise&lt;void&gt;): await fail(); Понятно, что на разворачивание/заворачивание промисов в таком случае будет тратиться как минимум один лишний цикл event loop, но ценой микроскопического оверхеда можно сильно стабилизировать систему на уровне подхода к коду. Заключение Как оказалось, ввиду малых последствий проблемный код пишут в основном те, кто не работал по-настоящему с NodeJS и встречались с JS только в браузере или очень небольшими кусками в NodeJS (без массового использования async/await). С тех пор как я осознал это, я использую вопрос про обработку ошибок и async/await на собеседованиях, что позволяет сразу понять: пользовался соискатель NodeJS по-настоящему или нет." />
<meta property="og:description" content="Введение Совершенно внезапно для себя около года назад я начал писать на NodeJS. Не очень хотелось, но выбор был небольшой — нужна кросс-сборка приложения и в браузер и на сервер. Оказалось, что для многих концепция async/await в JS — сложная тема. И, если в большинстве случаев TypeScript не даст совершить ошибку при работе с async/await, то в этой ситуации код получается корректный (с точки зрения синтаксиса и проверки типов), а программа работает не так, как задумывалось. Проблема Проблема возникает при отлове ошибки в async-функциях. Вопрос Приведу два примера: // --- Пример 1 async function something() { // ... return await someOtherAsyncFunction(); // ... // --- Пример 2 async function something() { // ... return someOtherAsyncFunction(); // ... Можете попробовать угадать, что не так с этим кодом? Даже eslint помечает код в примере 1 как некорректный, за что eslint отдельное “спасибо”. Ответ Теперь приведу код, запустив который будет понятно, что не так со вторым примером: async function fail() { throw new Error(&#39;Ultimate failure&#39;); } await (async () =&gt; { try { return await fail(); } catch (error) { console.log(&#39;The error was caught&#39;); } })(); await (async () =&gt; { try { return fail(); } catch (error) { console.log(&#39;The error was not caught&#39;); } })(); Как следует из кода выше, &#39;The error was not caught&#39; не будет выведен, потому что во втором случае ошибка не будет поймана. Объяснение Чтобы понять, почему так происходит, нужно немного копнуть вглубь async/await (но не слишком). Async/await — всего лишь обёртка над промисами, которые в свою очередь являются всего лишь обёрткой над колбеками. Сумма этих двух обёрток позволяет писать асинхронный (с колбеками) код в превдо-синхронном стиле (без колбеков). Async-функции Объявление функции с async позволяет в теле функции использовать await. Кроме этого, если результатом async-функции является не промис, async-функция автоматически заворачивает значение в промис (что-то вроде Promise.resolve(value)). Пример: async function returnNumber() { return 1; } console.log(returnNumber()); // Promise { 1 } И, наконец, если в теле async-функции происходит выбрасывание исключения, это исключение тоже автоматически заворачивается в промис (что-то вроде Promise.reject(exception)). Пример: async function fail() { throw new Error(&#39;Ultimate failure&#39;); } console.log(fail()); // Promise { &lt;rejected&gt; Error: Ultimate failure } Await и разворачивание промисов Await-же занимается разворачиванием промисов, возвращённых из той функции, которая вызывалась с ключевым словом await: async function returnNumber() { return 1; } console.log(await returnNumber()); // 1 И, если вернулся промис с reject‘ом, ошибка из этого промиса заново бросается (и затем заново возвращается через Promise.reject, если не будет поймана в try-catch): async function fail() { throw new Error(&#39;Ultimate failure&#39;); } console.log(await fail()); // console.log ничего не выведет, будет только &#39;Uncaught Error: Ultimate failure&#39; «Кто виноват?» и «Что делать?» В результате, если в последнем try-catch (вверх по стеку) не написать await перед потенциально-выбрасывающей-исключение-функцией, промис (с reject-ом) отправится как есть и блок try-catch не перейдёт в секцию catch. В таком случае исключение вместо обработки будет выброшено. И если в браузере выбрашенное исключение приведёт только к красной строчке в инспекторе, то в случае сервера весь процесс ляжет (если не пользоваться совсем неприличными способами вроде process.on(&#39;uncaughtException&#39;, (error: Error) =&gt; { /* ... */ });) и в лучшем случае будет автоматически перезапущен (потеряв все данные). Что делать? Стараться возвращать результаты асинхронных функций через await даже тогда, когда это кажется нелогичным внутри try-catch-блоков: try { const result = await fail(); return result; } catch (error) { logger.log(error); return undefined; } И всегда вызывать асинхронные функции через await — даже если те возвращают пустой промис (Promise&lt;void&gt;): await fail(); Понятно, что на разворачивание/заворачивание промисов в таком случае будет тратиться как минимум один лишний цикл event loop, но ценой микроскопического оверхеда можно сильно стабилизировать систему на уровне подхода к коду. Заключение Как оказалось, ввиду малых последствий проблемный код пишут в основном те, кто не работал по-настоящему с NodeJS и встречались с JS только в браузере или очень небольшими кусками в NodeJS (без массового использования async/await). С тех пор как я осознал это, я использую вопрос про обработку ошибок и async/await на собеседованиях, что позволяет сразу понять: пользовался соискатель NodeJS по-настоящему или нет." />
<link rel="canonical" href="https://ivalentinee.github.io/ru/programming/2023/03/15/async-await-exception-handling.html" />
<meta property="og:url" content="https://ivalentinee.github.io/ru/programming/2023/03/15/async-await-exception-handling.html" />
<meta property="og:site_name" content="ivalentinee" />
<meta property="og:type" content="article" />
<meta property="article:published_time" content="2023-03-15T00:00:00+00:00" />
<script type="application/ld+json">
{"mainEntityOfPage":{"@type":"WebPage","@id":"https://ivalentinee.github.io/ru/programming/2023/03/15/async-await-exception-handling.html"},"description":"Введение Совершенно внезапно для себя около года назад я начал писать на NodeJS. Не очень хотелось, но выбор был небольшой — нужна кросс-сборка приложения и в браузер и на сервер. Оказалось, что для многих концепция async/await в JS — сложная тема. И, если в большинстве случаев TypeScript не даст совершить ошибку при работе с async/await, то в этой ситуации код получается корректный (с точки зрения синтаксиса и проверки типов), а программа работает не так, как задумывалось. Проблема Проблема возникает при отлове ошибки в async-функциях. Вопрос Приведу два примера: // --- Пример 1 async function something() { // ... return await someOtherAsyncFunction(); // ... // --- Пример 2 async function something() { // ... return someOtherAsyncFunction(); // ... Можете попробовать угадать, что не так с этим кодом? Даже eslint помечает код в примере 1 как некорректный, за что eslint отдельное “спасибо”. Ответ Теперь приведу код, запустив который будет понятно, что не так со вторым примером: async function fail() { throw new Error(&#39;Ultimate failure&#39;); } await (async () =&gt; { try { return await fail(); } catch (error) { console.log(&#39;The error was caught&#39;); } })(); await (async () =&gt; { try { return fail(); } catch (error) { console.log(&#39;The error was not caught&#39;); } })(); Как следует из кода выше, &#39;The error was not caught&#39; не будет выведен, потому что во втором случае ошибка не будет поймана. Объяснение Чтобы понять, почему так происходит, нужно немного копнуть вглубь async/await (но не слишком). Async/await — всего лишь обёртка над промисами, которые в свою очередь являются всего лишь обёрткой над колбеками. Сумма этих двух обёрток позволяет писать асинхронный (с колбеками) код в превдо-синхронном стиле (без колбеков). Async-функции Объявление функции с async позволяет в теле функции использовать await. Кроме этого, если результатом async-функции является не промис, async-функция автоматически заворачивает значение в промис (что-то вроде Promise.resolve(value)). Пример: async function returnNumber() { return 1; } console.log(returnNumber()); // Promise { 1 } И, наконец, если в теле async-функции происходит выбрасывание исключения, это исключение тоже автоматически заворачивается в промис (что-то вроде Promise.reject(exception)). Пример: async function fail() { throw new Error(&#39;Ultimate failure&#39;); } console.log(fail()); // Promise { &lt;rejected&gt; Error: Ultimate failure } Await и разворачивание промисов Await-же занимается разворачиванием промисов, возвращённых из той функции, которая вызывалась с ключевым словом await: async function returnNumber() { return 1; } console.log(await returnNumber()); // 1 И, если вернулся промис с reject‘ом, ошибка из этого промиса заново бросается (и затем заново возвращается через Promise.reject, если не будет поймана в try-catch): async function fail() { throw new Error(&#39;Ultimate failure&#39;); } console.log(await fail()); // console.log ничего не выведет, будет только &#39;Uncaught Error: Ultimate failure&#39; «Кто виноват?» и «Что делать?» В результате, если в последнем try-catch (вверх по стеку) не написать await перед потенциально-выбрасывающей-исключение-функцией, промис (с reject-ом) отправится как есть и блок try-catch не перейдёт в секцию catch. В таком случае исключение вместо обработки будет выброшено. И если в браузере выбрашенное исключение приведёт только к красной строчке в инспекторе, то в случае сервера весь процесс ляжет (если не пользоваться совсем неприличными способами вроде process.on(&#39;uncaughtException&#39;, (error: Error) =&gt; { /* ... */ });) и в лучшем случае будет автоматически перезапущен (потеряв все данные). Что делать? Стараться возвращать результаты асинхронных функций через await даже тогда, когда это кажется нелогичным внутри try-catch-блоков: try { const result = await fail(); return result; } catch (error) { logger.log(error); return undefined; } И всегда вызывать асинхронные функции через await — даже если те возвращают пустой промис (Promise&lt;void&gt;): await fail(); Понятно, что на разворачивание/заворачивание промисов в таком случае будет тратиться как минимум один лишний цикл event loop, но ценой микроскопического оверхеда можно сильно стабилизировать систему на уровне подхода к коду. Заключение Как оказалось, ввиду малых последствий проблемный код пишут в основном те, кто не работал по-настоящему с NodeJS и встречались с JS только в браузере или очень небольшими кусками в NodeJS (без массового использования async/await). С тех пор как я осознал это, я использую вопрос про обработку ошибок и async/await на собеседованиях, что позволяет сразу понять: пользовался соискатель NodeJS по-настоящему или нет.","@type":"BlogPosting","url":"https://ivalentinee.github.io/ru/programming/2023/03/15/async-await-exception-handling.html","headline":"Обработка ошибок в async/await","dateModified":"2023-03-15T00:00:00+00:00","datePublished":"2023-03-15T00:00:00+00:00","@context":"http://schema.org"}</script>
<!-- End Jekyll SEO tag -->
<link rel="stylesheet" href="/assets/main.css"><link type="application/atom+xml" rel="alternate" href="https://ivalentinee.github.io/feed.xml" title="ivalentinee" /></head>
<body><header class="site-header" role="banner">

  <div class="wrapper">
    
    
    <a class="site-title" href="/ru/">ivalentinee</a>

    
      <nav class="site-nav">
        <input type="checkbox" id="nav-trigger" class="nav-trigger" />
        <label for="nav-trigger">
          <span class="menu-icon">
            <svg viewBox="0 0 18 15" width="18px" height="15px">
              <path fill="#424242" d="M18,1.484c0,0.82-0.665,1.484-1.484,1.484H1.484C0.665,2.969,0,2.304,0,1.484l0,0C0,0.665,0.665,0,1.484,0 h15.031C17.335,0,18,0.665,18,1.484L18,1.484z"/>
              <path fill="#424242" d="M18,7.516C18,8.335,17.335,9,16.516,9H1.484C0.665,9,0,8.335,0,7.516l0,0c0-0.82,0.665-1.484,1.484-1.484 h15.031C17.335,6.031,18,6.696,18,7.516L18,7.516z"/>
              <path fill="#424242" d="M18,13.516C18,14.335,17.335,15,16.516,15H1.484C0.665,15,0,14.335,0,13.516l0,0 c0-0.82,0.665-1.484,1.484-1.484h15.031C17.335,12.031,18,12.696,18,13.516L18,13.516z"/>
            </svg>
          </span>
        </label>

        <div class="trigger">
          
            
            
              
            
          
            
            
              
                <a class="page-link" href="/ru/about/">Обо мне</a>
              
            
          
            
            
              
            
          
            
            
              
            
          
            
            
              
            
          
            
            
              
            
          
            
            
              
            
          
            
            
          
            
            
          
            
            
              
            
          
            
            
          
            
            
              
            
          
            
            
              
            
          
            
            
          
            
            
              
            
          
            
            
              
            
          
            
            
              
            
          
            
            
              
            
          
            
            
          
        </div>
      </nav>
    
  </div>
</header>
<main class="page-content" aria-label="Content">
      <div class="wrapper">
        <article class="post" itemscope itemtype="http://schema.org/BlogPosting">

  <header class="post-header">
    <h1 class="post-title" itemprop="name headline">Обработка ошибок в async/await</h1>
    <p class="post-meta">
      <time datetime="2023-03-15T00:00:00+00:00" itemprop="datePublished">
        
        Mar 15, 2023
      </time>
      </p>
  </header>

          <div class="language-selector">
          <a href="/en/programming/2023/03/15/async-await-exception-handling.html" class="language-selector-link">English</a><span class="language-selector-separator">|</span><span class="language-selector-link">Русский</span>
        </div>


  <div class="post-content" itemprop="articleBody">
    <h2 id="введение">Введение</h2>
<p>Совершенно внезапно для себя около года назад я начал писать на NodeJS. Не очень хотелось, но выбор был небольшой — нужна кросс-сборка приложения и в браузер и на сервер.</p>

<p>Оказалось, что для многих концепция async/await в JS — сложная тема. И, если в большинстве случаев TypeScript не даст совершить ошибку при работе с async/await, то в этой ситуации код получается корректный (с точки зрения синтаксиса и проверки типов), а программа работает не так, как задумывалось.</p>

<h2 id="проблема">Проблема</h2>
<p>Проблема возникает при отлове ошибки в async-функциях.</p>

<h3 id="вопрос">Вопрос</h3>
<p>Приведу два примера:</p>
<div class="language-js highlighter-rouge"><div class="highlight"><pre class="highlight"><code><span class="c1">// --- Пример 1</span>
<span class="k">async</span> <span class="kd">function</span> <span class="nx">something</span><span class="p">()</span> <span class="p">{</span>
<span class="c1">// ...</span>
  <span class="k">return</span> <span class="kr">await</span> <span class="nx">someOtherAsyncFunction</span><span class="p">();</span>
<span class="c1">// ...</span>
</code></pre></div></div>
<div class="language-js highlighter-rouge"><div class="highlight"><pre class="highlight"><code><span class="c1">// --- Пример 2</span>
<span class="k">async</span> <span class="kd">function</span> <span class="nx">something</span><span class="p">()</span> <span class="p">{</span>
<span class="c1">// ...</span>
  <span class="k">return</span> <span class="nx">someOtherAsyncFunction</span><span class="p">();</span>
<span class="c1">// ...</span>
</code></pre></div></div>
<p>Можете попробовать угадать, что не так с этим кодом?</p>

<p>Даже eslint помечает код в примере 1 как некорректный, за что eslint отдельное “спасибо”.</p>

<h3 id="ответ">Ответ</h3>
<p>Теперь приведу код, запустив который будет понятно, что не так со вторым примером:</p>
<div class="language-js highlighter-rouge"><div class="highlight"><pre class="highlight"><code><span class="k">async</span> <span class="kd">function</span> <span class="nx">fail</span><span class="p">()</span> <span class="p">{</span>
  <span class="k">throw</span> <span class="k">new</span> <span class="nb">Error</span><span class="p">(</span><span class="s1">'Ultimate failure'</span><span class="p">);</span>
<span class="p">}</span>

<span class="kr">await</span> <span class="p">(</span><span class="k">async</span> <span class="p">()</span> <span class="o">=&gt;</span> <span class="p">{</span>
  <span class="k">try</span> <span class="p">{</span>
    <span class="k">return</span> <span class="kr">await</span> <span class="nx">fail</span><span class="p">();</span>
  <span class="p">}</span> <span class="k">catch</span> <span class="p">(</span><span class="nx">error</span><span class="p">)</span> <span class="p">{</span>
    <span class="nx">console</span><span class="p">.</span><span class="nx">log</span><span class="p">(</span><span class="s1">'The error was caught'</span><span class="p">);</span>
  <span class="p">}</span>
<span class="p">})();</span>

<span class="kr">await</span> <span class="p">(</span><span class="k">async</span> <span class="p">()</span> <span class="o">=&gt;</span> <span class="p">{</span>
  <span class="k">try</span> <span class="p">{</span>
    <span class="k">return</span> <span class="nx">fail</span><span class="p">();</span>
  <span class="p">}</span> <span class="k">catch</span> <span class="p">(</span><span class="nx">error</span><span class="p">)</span> <span class="p">{</span>
    <span class="nx">console</span><span class="p">.</span><span class="nx">log</span><span class="p">(</span><span class="s1">'The error was not caught'</span><span class="p">);</span>
  <span class="p">}</span>
<span class="p">})();</span>
</code></pre></div></div>
<p>Как следует из кода выше, <code class="highlighter-rouge">'The error was not caught'</code> не будет выведен, потому что во втором случае ошибка не будет поймана.</p>

<h3 id="объяснение">Объяснение</h3>
<p>Чтобы понять, почему так происходит, нужно немного копнуть вглубь async/await (но не слишком).</p>

<p><a href="https://developer.mozilla.org/en-US/docs/Web/JavaScript/Reference/Statements/async_function">Async/await</a> — всего лишь обёртка над <a href="https://developer.mozilla.org/en-US/docs/Web/JavaScript/Reference/Global_Objects/Promise">промисами</a>, которые в свою очередь являются всего лишь обёрткой над колбеками. Сумма этих двух обёрток позволяет писать асинхронный (с колбеками) код в превдо-синхронном стиле (без колбеков).</p>

<h4 id="async-функции">Async-функции</h4>
<p>Объявление функции с <code class="highlighter-rouge">async</code> позволяет в теле функции использовать <code class="highlighter-rouge">await</code>.</p>

<p>Кроме этого, если результатом async-функции является не промис, async-функция автоматически заворачивает значение в промис (что-то вроде <code class="highlighter-rouge">Promise.resolve(value)</code>).<br />
Пример:</p>
<div class="language-js highlighter-rouge"><div class="highlight"><pre class="highlight"><code><span class="k">async</span> <span class="kd">function</span> <span class="nx">returnNumber</span><span class="p">()</span> <span class="p">{</span>
  <span class="k">return</span> <span class="mi">1</span><span class="p">;</span>
<span class="p">}</span>

<span class="nx">console</span><span class="p">.</span><span class="nx">log</span><span class="p">(</span><span class="nx">returnNumber</span><span class="p">());</span>

<span class="c1">// Promise { 1 }</span>
</code></pre></div></div>

<p>И, наконец, если в теле async-функции происходит выбрасывание исключения, это исключение тоже автоматически заворачивается в промис (что-то вроде <code class="highlighter-rouge">Promise.reject(exception)</code>).<br />
Пример:</p>
<div class="language-js highlighter-rouge"><div class="highlight"><pre class="highlight"><code><span class="k">async</span> <span class="kd">function</span> <span class="nx">fail</span><span class="p">()</span> <span class="p">{</span>
  <span class="k">throw</span> <span class="k">new</span> <span class="nb">Error</span><span class="p">(</span><span class="s1">'Ultimate failure'</span><span class="p">);</span>
<span class="p">}</span>

<span class="nx">console</span><span class="p">.</span><span class="nx">log</span><span class="p">(</span><span class="nx">fail</span><span class="p">());</span>

<span class="c1">// Promise { &lt;rejected&gt; Error: Ultimate failure }</span>
</code></pre></div></div>

<h4 id="await-и-разворачивание-промисов">Await и разворачивание промисов</h4>
<p>Await-же занимается разворачиванием промисов, возвращённых из той функции, которая вызывалась с ключевым словом <code class="highlighter-rouge">await</code>:</p>
<div class="language-js highlighter-rouge"><div class="highlight"><pre class="highlight"><code><span class="k">async</span> <span class="kd">function</span> <span class="nx">returnNumber</span><span class="p">()</span> <span class="p">{</span>
  <span class="k">return</span> <span class="mi">1</span><span class="p">;</span>
<span class="p">}</span>

<span class="nx">console</span><span class="p">.</span><span class="nx">log</span><span class="p">(</span><span class="kr">await</span> <span class="nx">returnNumber</span><span class="p">());</span>

<span class="c1">// 1</span>
</code></pre></div></div>

<p>И, если вернулся промис с <code class="highlighter-rouge">reject</code>‘ом, ошибка из этого промиса заново бросается (и затем заново возвращается через Promise.reject, если не будет поймана в try-catch):</p>
<div class="language-js highlighter-rouge"><div class="highlight"><pre class="highlight"><code><span class="k">async</span> <span class="kd">function</span> <span class="nx">fail</span><span class="p">()</span> <span class="p">{</span>
  <span class="k">throw</span> <span class="k">new</span> <span class="nb">Error</span><span class="p">(</span><span class="s1">'Ultimate failure'</span><span class="p">);</span>
<span class="p">}</span>

<span class="nx">console</span><span class="p">.</span><span class="nx">log</span><span class="p">(</span><span class="kr">await</span> <span class="nx">fail</span><span class="p">());</span>

<span class="c1">// console.log ничего не выведет, будет только 'Uncaught Error: Ultimate failure'</span>
</code></pre></div></div>

<h3 id="кто-виноват-и-что-делать">«Кто виноват?» и «Что делать?»</h3>
<p>В результате, если в последнем try-catch (вверх по стеку) не написать await перед потенциально-выбрасывающей-исключение-функцией, промис (с <code class="highlighter-rouge">reject</code>-ом) отправится как есть и блок try-catch не перейдёт в секцию catch. В таком случае исключение вместо обработки будет выброшено.</p>

<p>И если в браузере выбрашенное исключение приведёт только к красной строчке в инспекторе, то в случае сервера весь процесс ляжет (если не пользоваться совсем неприличными способами вроде <code class="highlighter-rouge">process.on('uncaughtException', (error: Error) =&gt; { /* ... */ });</code>) и в лучшем случае будет автоматически перезапущен (потеряв все данные).</p>

<p>Что делать? Стараться возвращать результаты асинхронных функций через <code class="highlighter-rouge">await</code> даже тогда, когда это кажется нелогичным внутри try-catch-блоков:</p>
<div class="language-js highlighter-rouge"><div class="highlight"><pre class="highlight"><code><span class="k">try</span> <span class="p">{</span>
  <span class="kd">const</span> <span class="nx">result</span> <span class="o">=</span> <span class="kr">await</span> <span class="nx">fail</span><span class="p">();</span>
  <span class="k">return</span> <span class="nx">result</span><span class="p">;</span>
<span class="p">}</span> <span class="k">catch</span> <span class="p">(</span><span class="nx">error</span><span class="p">)</span> <span class="p">{</span>
  <span class="nx">logger</span><span class="p">.</span><span class="nx">log</span><span class="p">(</span><span class="nx">error</span><span class="p">);</span>
  <span class="k">return</span> <span class="kc">undefined</span><span class="p">;</span>
<span class="p">}</span>

</code></pre></div></div>
<p>И всегда вызывать асинхронные функции через await — даже если те возвращают пустой промис (<code class="highlighter-rouge">Promise&lt;void&gt;</code>):</p>
<div class="language-js highlighter-rouge"><div class="highlight"><pre class="highlight"><code><span class="kr">await</span> <span class="nx">fail</span><span class="p">();</span>
</code></pre></div></div>

<p>Понятно, что на разворачивание/заворачивание промисов в таком случае будет тратиться как минимум один лишний цикл event loop, но ценой микроскопического оверхеда можно сильно стабилизировать систему на уровне подхода к коду.</p>

<h2 id="заключение">Заключение</h2>
<p>Как оказалось, ввиду малых последствий проблемный код пишут в основном те, кто не работал по-настоящему с NodeJS и встречались с JS только в браузере или очень небольшими кусками в NodeJS (без массового использования async/await).</p>

<p>С тех пор как я осознал это, я использую вопрос про обработку ошибок и async/await на собеседованиях, что позволяет сразу понять: пользовался соискатель NodeJS по-настоящему или нет.</p>

  </div>

  

  
</article>

      </div>
    </main><footer class="site-footer h-card">
  <data class="u-url" href="/"></data>

  <div class="wrapper">

    <h2 class="footer-heading">ivalentinee</h2>

    <div class="footer-col-wrapper">
      <div class="footer-col footer-col-1">
        <ul class="contact-list">
          <li class="p-name">ivalentinee</li><li><a class="u-email" href="mailto:valentine.emperor@gmail.com">valentine.emperor@gmail.com</a></li></ul>
      </div>

      <div class="footer-col footer-col-2"><ul class="social-media-list"><li><a href="https://github.com/ivalentinee"><svg class="svg-icon"><use xlink:href="/assets/minima-social-icons.svg#github"></use></svg> <span class="username">ivalentinee</span></a></li></ul>
</div>

      <div class="footer-col footer-col-3">
        <p></p>
      </div>
    </div>

  </div>

</footer>
</body>

</html>
